Workbook

Sheet Reference
A1: Reference data
A2: Transcribed from the site profile, the programme brief and the vendor notice. Blue cells are typed source data; everything on the other sheets computes from here.
A4: Programme week 1 commences | B4: 46272
A5: Deployment teams | B5: 3
A6: Validation weeks, regulated site | B6: 12
A7: Legacy support ends | B7: 46568
A8: Support ends, programme week | B8: =INT((B7-B4)/7)+1
A10: Code | B10: Site | C10: Country | D10: Users | E10: Master data owned | F10: Depends on | G10: Weeks | H10: Shutdown week | I10: GMP
A11: BRD | B11: Bridgnorth | C11: United Kingdom | D11: 610 | E11: Material master | G11: 5 | I11: No
A12: HAL | B12: Halesworth | C12: United Kingdom | D12: 240 | E12: Customer master | G12: 4 | I12: No
A13: KIN | B13: Kinloss | C13: United Kingdom | D13: 180 | E13: Vendor master | G13: 4 | I13: No
A14: ANT | B14: Antwerp | C14: Belgium | D14: 520 | F14: BRD, KIN | G14: 5 | I14: No
A15: ROT | B15: Rotterdam | C15: Netherlands | D15: 460 | F15: BRD, KIN | G15: 4 | I15: No
A16: LYO | B16: Lyon | C16: France | D16: 310 | F16: BRD | G16: 4 | I16: No
A17: TUR | B17: Turin | C17: Italy | D17: 290 | F17: BRD | G17: 4 | I17: No
A18: VAL | B18: Valencia | C18: Spain | D18: 205 | F18: BRD | G18: 3 | I18: No
A19: GDA | B19: Gdansk | C19: Poland | D19: 340 | F19: BRD, HAL | G19: 4 | I19: No
A20: CHA | B20: Charleston | C20: United States | D20: 580 | F20: BRD, HAL | G20: 5 | I20: No
A21: MOB | B21: Mobile | C21: United States | D21: 395 | F21: BRD, HAL | G21: 4 | H21: 33 | I21: No
A22: SAR | B22: Sarnia | C22: Canada | D22: 260 | F22: BRD, HAL | G22: 4 | H22: 24 | I22: No
A23: PEN | B23: Penang | C23: Malaysia | D23: 215 | F23: BRD | G23: 3 | I23: No
A24: COR | B24: Cork | C24: Ireland | D24: 150 | F24: BRD, KIN | G24: 3 | I24: Yes
A26: Financial blackout weeks | B26: 3 | C26: 4 | D26: 16 | E26: 17 | F26: 18 | G26: 19 | H26: 20 | I26: 29 | J26: 30 | K26: 42 | L26: 43

Sheet Plan
A1: Verwood Specialty Chemicals ERP cutover sequence
A2: Blue cells are the three planning decisions per site: wave, team and start week. Every other column computes from the Reference sheet.
A4: Wave | B4: Code | C4: Site | D4: Country | E4: Users | F4: Team | G4: Start week | H4: Week commencing | I4: Weeks | J4: End week | K4: Live week | L4: Live date | M4: Binding constraint
A5: 1 | B5: BRD | C5: =INDEX(Reference!$B$11:$B$24,MATCH($B5,Reference!$A$11:$A$24,0)) | D5: =INDEX(Reference!$C$11:$C$24,MATCH($B5,Reference!$A$11:$A$24,0)) | E5: =INDEX(Reference!$D$11:$D$24,MATCH($B5,Reference!$A$11:$A$24,0)) | F5: 1 | G5: 5 | H5: =Reference!$B$4+($G5-1)*7 | I5: =INDEX(Reference!$G$11:$G$24,MATCH($B5,Reference!$A$11:$A$24,0)) | J5: =$G5+$I5-1 | K5: =$J5+1+IF(INDEX(Reference!$I$11:$I$24,MATCH($B5,Reference!$A$11:$A$24,0))="Yes",Reference!$B$6,0) | L5: =Reference!$B$4+($K5-1)*7 | M5: Owns material master; 11 sites depend on it
A6: 1 | B6: HAL | C6: =INDEX(Reference!$B$11:$B$24,MATCH($B6,Reference!$A$11:$A$24,0)) | D6: =INDEX(Reference!$C$11:$C$24,MATCH($B6,Reference!$A$11:$A$24,0)) | E6: =INDEX(Reference!$D$11:$D$24,MATCH($B6,Reference!$A$11:$A$24,0)) | F6: 2 | G6: 5 | H6: =Reference!$B$4+($G6-1)*7 | I6: =INDEX(Reference!$G$11:$G$24,MATCH($B6,Reference!$A$11:$A$24,0)) | J6: =$G6+$I6-1 | K6: =$J6+1+IF(INDEX(Reference!$I$11:$I$24,MATCH($B6,Reference!$A$11:$A$24,0))="Yes",Reference!$B$6,0) | L6: =Reference!$B$4+($K6-1)*7 | M6: Owns customer master; 4 sites depend on it
A7: 1 | B7: KIN | C7: =INDEX(Reference!$B$11:$B$24,MATCH($B7,Reference!$A$11:$A$24,0)) | D7: =INDEX(Reference!$C$11:$C$24,MATCH($B7,Reference!$A$11:$A$24,0)) | E7: =INDEX(Reference!$D$11:$D$24,MATCH($B7,Reference!$A$11:$A$24,0)) | F7: 3 | G7: 5 | H7: =Reference!$B$4+($G7-1)*7 | I7: =INDEX(Reference!$G$11:$G$24,MATCH($B7,Reference!$A$11:$A$24,0)) | J7: =$G7+$I7-1 | K7: =$J7+1+IF(INDEX(Reference!$I$11:$I$24,MATCH($B7,Reference!$A$11:$A$24,0))="Yes",Reference!$B$6,0) | L7: =Reference!$B$4+($K7-1)*7 | M7: Owns vendor master; 3 sites depend on it
A8: 2 | B8: CHA | C8: =INDEX(Reference!$B$11:$B$24,MATCH($B8,Reference!$A$11:$A$24,0)) | D8: =INDEX(Reference!$C$11:$C$24,MATCH($B8,Reference!$A$11:$A$24,0)) | E8: =INDEX(Reference!$D$11:$D$24,MATCH($B8,Reference!$A$11:$A$24,0)) | F8: 3 | G8: 10 | H8: =Reference!$B$4+($G8-1)*7 | I8: =INDEX(Reference!$G$11:$G$24,MATCH($B8,Reference!$A$11:$A$24,0)) | J8: =$G8+$I8-1 | K8: =$J8+1+IF(INDEX(Reference!$I$11:$I$24,MATCH($B8,Reference!$A$11:$A$24,0))="Yes",Reference!$B$6,0) | L8: =Reference!$B$4+($K8-1)*7 | M8: Follows BRD, HAL
A9: 2 | B9: COR | C9: =INDEX(Reference!$B$11:$B$24,MATCH($B9,Reference!$A$11:$A$24,0)) | D9: =INDEX(Reference!$C$11:$C$24,MATCH($B9,Reference!$A$11:$A$24,0)) | E9: =INDEX(Reference!$D$11:$D$24,MATCH($B9,Reference!$A$11:$A$24,0)) | F9: 2 | G9: 10 | H9: =Reference!$B$4+($G9-1)*7 | I9: =INDEX(Reference!$G$11:$G$24,MATCH($B9,Reference!$A$11:$A$24,0)) | J9: =$G9+$I9-1 | K9: =$J9+1+IF(INDEX(Reference!$I$11:$I$24,MATCH($B9,Reference!$A$11:$A$24,0))="Yes",Reference!$B$6,0) | L9: =Reference!$B$4+($K9-1)*7 | M9: Validation runs after cutover, so it must start early despite being the smallest site
A10: 3 | B10: ANT | C10: =INDEX(Reference!$B$11:$B$24,MATCH($B10,Reference!$A$11:$A$24,0)) | D10: =INDEX(Reference!$C$11:$C$24,MATCH($B10,Reference!$A$11:$A$24,0)) | E10: =INDEX(Reference!$D$11:$D$24,MATCH($B10,Reference!$A$11:$A$24,0)) | F10: 2 | G10: 21 | H10: =Reference!$B$4+($G10-1)*7 | I10: =INDEX(Reference!$G$11:$G$24,MATCH($B10,Reference!$A$11:$A$24,0)) | J10: =$G10+$I10-1 | K10: =$J10+1+IF(INDEX(Reference!$I$11:$I$24,MATCH($B10,Reference!$A$11:$A$24,0))="Yes",Reference!$B$6,0) | L10: =Reference!$B$4+($K10-1)*7 | M10: Follows BRD, KIN
A11: 3 | B11: ROT | C11: =INDEX(Reference!$B$11:$B$24,MATCH($B11,Reference!$A$11:$A$24,0)) | D11: =INDEX(Reference!$C$11:$C$24,MATCH($B11,Reference!$A$11:$A$24,0)) | E11: =INDEX(Reference!$D$11:$D$24,MATCH($B11,Reference!$A$11:$A$24,0)) | F11: 3 | G11: 21 | H11: =Reference!$B$4+($G11-1)*7 | I11: =INDEX(Reference!$G$11:$G$24,MATCH($B11,Reference!$A$11:$A$24,0)) | J11: =$G11+$I11-1 | K11: =$J11+1+IF(INDEX(Reference!$I$11:$I$24,MATCH($B11,Reference!$A$11:$A$24,0))="Yes",Reference!$B$6,0) | L11: =Reference!$B$4+($K11-1)*7 | M11: Follows BRD, KIN
A12: 4 | B12: SAR | C12: =INDEX(Reference!$B$11:$B$24,MATCH($B12,Reference!$A$11:$A$24,0)) | D12: =INDEX(Reference!$C$11:$C$24,MATCH($B12,Reference!$A$11:$A$24,0)) | E12: =INDEX(Reference!$D$11:$D$24,MATCH($B12,Reference!$A$11:$A$24,0)) | F12: 1 | G12: 24 | H12: =Reference!$B$4+($G12-1)*7 | I12: =INDEX(Reference!$G$11:$G$24,MATCH($B12,Reference!$A$11:$A$24,0)) | J12: =$G12+$I12-1 | K12: =$J12+1+IF(INDEX(Reference!$I$11:$I$24,MATCH($B12,Reference!$A$11:$A$24,0))="Yes",Reference!$B$6,0) | L12: =Reference!$B$4+($K12-1)*7 | M12: Can only start in its annual shutdown window
A13: 4 | B13: GDA | C13: =INDEX(Reference!$B$11:$B$24,MATCH($B13,Reference!$A$11:$A$24,0)) | D13: =INDEX(Reference!$C$11:$C$24,MATCH($B13,Reference!$A$11:$A$24,0)) | E13: =INDEX(Reference!$D$11:$D$24,MATCH($B13,Reference!$A$11:$A$24,0)) | F13: 3 | G13: 25 | H13: =Reference!$B$4+($G13-1)*7 | I13: =INDEX(Reference!$G$11:$G$24,MATCH($B13,Reference!$A$11:$A$24,0)) | J13: =$G13+$I13-1 | K13: =$J13+1+IF(INDEX(Reference!$I$11:$I$24,MATCH($B13,Reference!$A$11:$A$24,0))="Yes",Reference!$B$6,0) | L13: =Reference!$B$4+($K13-1)*7 | M13: Follows BRD, HAL
A14: 5 | B14: LYO | C14: =INDEX(Reference!$B$11:$B$24,MATCH($B14,Reference!$A$11:$A$24,0)) | D14: =INDEX(Reference!$C$11:$C$24,MATCH($B14,Reference!$A$11:$A$24,0)) | E14: =INDEX(Reference!$D$11:$D$24,MATCH($B14,Reference!$A$11:$A$24,0)) | F14: 2 | G14: 31 | H14: =Reference!$B$4+($G14-1)*7 | I14: =INDEX(Reference!$G$11:$G$24,MATCH($B14,Reference!$A$11:$A$24,0)) | J14: =$G14+$I14-1 | K14: =$J14+1+IF(INDEX(Reference!$I$11:$I$24,MATCH($B14,Reference!$A$11:$A$24,0))="Yes",Reference!$B$6,0) | L14: =Reference!$B$4+($K14-1)*7 | M14: Follows BRD
A15: 5 | B15: TUR | C15: =INDEX(Reference!$B$11:$B$24,MATCH($B15,Reference!$A$11:$A$24,0)) | D15: =INDEX(Reference!$C$11:$C$24,MATCH($B15,Reference!$A$11:$A$24,0)) | E15: =INDEX(Reference!$D$11:$D$24,MATCH($B15,Reference!$A$11:$A$24,0)) | F15: 3 | G15: 31 | H15: =Reference!$B$4+($G15-1)*7 | I15: =INDEX(Reference!$G$11:$G$24,MATCH($B15,Reference!$A$11:$A$24,0)) | J15: =$G15+$I15-1 | K15: =$J15+1+IF(INDEX(Reference!$I$11:$I$24,MATCH($B15,Reference!$A$11:$A$24,0))="Yes",Reference!$B$6,0) | L15: =Reference!$B$4+($K15-1)*7 | M15: Follows BRD
A16: 6 | B16: MOB | C16: =INDEX(Reference!$B$11:$B$24,MATCH($B16,Reference!$A$11:$A$24,0)) | D16: =INDEX(Reference!$C$11:$C$24,MATCH($B16,Reference!$A$11:$A$24,0)) | E16: =INDEX(Reference!$D$11:$D$24,MATCH($B16,Reference!$A$11:$A$24,0)) | F16: 1 | G16: 33 | H16: =Reference!$B$4+($G16-1)*7 | I16: =INDEX(Reference!$G$11:$G$24,MATCH($B16,Reference!$A$11:$A$24,0)) | J16: =$G16+$I16-1 | K16: =$J16+1+IF(INDEX(Reference!$I$11:$I$24,MATCH($B16,Reference!$A$11:$A$24,0))="Yes",Reference!$B$6,0) | L16: =Reference!$B$4+($K16-1)*7 | M16: Can only start in its annual shutdown window
... A18: 7 | B18: VAL | C18: =INDEX(Reference!$B$11:$B$24,MATCH($B18,Reference!$A$11:$A$24,0)) | D18: =INDEX(Reference!$C$11:$C$24,MATCH($B18,Reference!$A$11:$A$24,0)) | E18: =INDEX(Reference!$D$11:$D$24,MATCH($B18,Reference!$A$11:$A$24,0)) | F18: 3 | G18: 35 | H18: =Reference!$B$4+($G18-1)*7 | I18: =INDEX(Reference!$G$11:$G$24,MATCH($B18,Reference!$A$11:$A$24,0)) | J18: =$G18+$I18-1 | K18: =$J18+1+IF(INDEX(Reference!$I$11:$I$24,MATCH($B18,Reference!$A$11:$A$24,0))="Yes",Reference!$B$6,0) | L18: =Reference!$B$4+($K18-1)*7 | M18: Follows BRD
B19: TOTAL | E19: =SUM(E5:E18) | I19: =SUM(I5:I18) | K19: =MAX(K5:K18) | L19: =Reference!$B$4+(K19-1)*7 | M19: Last go-live across the programme
B20: Support deadline | E20: =Reference!$B$8 | K20: =Reference!$B$8 | L20: =Reference!$B$7 | M20: Programme week in which legacy support ends
B21: Float to the deadline | E21: =Reference!$B$8-K19 | M21: Weeks between the last go-live and the end of support

Sheet Timeline
A1: Team loading by programme week
A2: Every cell computes from the Plan sheet. Row 3 flags the financial blackout weeks.
A3: Blackout | B3: =IF(COUNTIF(Reference!$B$26:$L$26,B$4)>0,1,0) | C3: =IF(COUNTIF(Reference!$B$26:$L$26,C$4)>0,1,0) | D3: =IF(COUNTIF(Reference!$B$26:$L$26,D$4)>0,1,0) | E3: =IF(COUNTIF(Reference!$B$26:$L$26,E$4)>0,1,0) | F3: =IF(COUNTIF(Reference!$B$26:$L$26,F$4)>0,1,0) | G3: =IF(COUNTIF(Reference!$B$26:$L$26,G$4)>0,1,0) | H3: =IF(COUNTIF(Reference!$B$26:$L$26,H$4)>0,1,0) | I3: =IF(COUNTIF(Reference!$B$26:$L$26,I$4)>0,1,0) | ... AR3: =IF(COUNTIF(Reference!$B$26:$L$26,AR$4)>0,1,0)
A4: Code | B4: 1 | C4: =B4+1 | D4: =C4+1 | E4: =D4+1 | F4: =E4+1 | G4: =F4+1 | H4: =G4+1 | I4: =H4+1 | J4: =I4+1 | ... AR4: =AQ4+1
A5: =Plan!$B5 | B5: =IF(AND(Plan!$G5<=B$4,Plan!$J5>=B$4),Plan!$B5,"") | C5: =IF(AND(Plan!$G5<=C$4,Plan!$J5>=C$4),Plan!$B5,"") | D5: =IF(AND(Plan!$G5<=D$4,Plan!$J5>=D$4),Plan!$B5,"") | E5: =IF(AND(Plan!$G5<=E$4,Plan!$J5>=E$4),Plan!$B5,"") | F5: =IF(AND(Plan!$G5<=F$4,Plan!$J5>=F$4),Plan!$B5,"") | G5: =IF(AND(Plan!$G5<=G$4,Plan!$J5>=G$4),Plan!$B5,"") | H5: =IF(AND(Plan!$G5<=H$4,Plan!$J5>=H$4),Plan!$B5,"") | I5: =IF(AND(Plan!$G5<=I$4,Plan!$J5>=I$4),Plan!$B5,"") | ... AR5: =IF(AND(Plan!$G5<=AR$4,Plan!$J5>=AR$4),Plan!$B5,"")
A6: =Plan!$B6 | B6: =IF(AND(Plan!$G6<=B$4,Plan!$J6>=B$4),Plan!$B6,"") | C6: =IF(AND(Plan!$G6<=C$4,Plan!$J6>=C$4),Plan!$B6,"") | D6: =IF(AND(Plan!$G6<=D$4,Plan!$J6>=D$4),Plan!$B6,"") | E6: =IF(AND(Plan!$G6<=E$4,Plan!$J6>=E$4),Plan!$B6,"") | F6: =IF(AND(Plan!$G6<=F$4,Plan!$J6>=F$4),Plan!$B6,"") | G6: =IF(AND(Plan!$G6<=G$4,Plan!$J6>=G$4),Plan!$B6,"") | H6: =IF(AND(Plan!$G6<=H$4,Plan!$J6>=H$4),Plan!$B6,"") | I6: =IF(AND(Plan!$G6<=I$4,Plan!$J6>=I$4),Plan!$B6,"") | ... AR6: =IF(AND(Plan!$G6<=AR$4,Plan!$J6>=AR$4),Plan!$B6,"")
A7: =Plan!$B7 | B7: =IF(AND(Plan!$G7<=B$4,Plan!$J7>=B$4),Plan!$B7,"") | C7: =IF(AND(Plan!$G7<=C$4,Plan!$J7>=C$4),Plan!$B7,"") | D7: =IF(AND(Plan!$G7<=D$4,Plan!$J7>=D$4),Plan!$B7,"") | E7: =IF(AND(Plan!$G7<=E$4,Plan!$J7>=E$4),Plan!$B7,"") | F7: =IF(AND(Plan!$G7<=F$4,Plan!$J7>=F$4),Plan!$B7,"") | G7: =IF(AND(Plan!$G7<=G$4,Plan!$J7>=G$4),Plan!$B7,"") | H7: =IF(AND(Plan!$G7<=H$4,Plan!$J7>=H$4),Plan!$B7,"") | I7: =IF(AND(Plan!$G7<=I$4,Plan!$J7>=I$4),Plan!$B7,"") | ... AR7: =IF(AND(Plan!$G7<=AR$4,Plan!$J7>=AR$4),Plan!$B7,"")
A8: =Plan!$B8 | B8: =IF(AND(Plan!$G8<=B$4,Plan!$J8>=B$4),Plan!$B8,"") | C8: =IF(AND(Plan!$G8<=C$4,Plan!$J8>=C$4),Plan!$B8,"") | D8: =IF(AND(Plan!$G8<=D$4,Plan!$J8>=D$4),Plan!$B8,"") | E8: =IF(AND(Plan!$G8<=E$4,Plan!$J8>=E$4),Plan!$B8,"") | F8: =IF(AND(Plan!$G8<=F$4,Plan!$J8>=F$4),Plan!$B8,"") | G8: =IF(AND(Plan!$G8<=G$4,Plan!$J8>=G$4),Plan!$B8,"") | H8: =IF(AND(Plan!$G8<=H$4,Plan!$J8>=H$4),Plan!$B8,"") | I8: =IF(AND(Plan!$G8<=I$4,Plan!$J8>=I$4),Plan!$B8,"") | ... AR8: =IF(AND(Plan!$G8<=AR$4,Plan!$J8>=AR$4),Plan!$B8,"")
A9: =Plan!$B9 | B9: =IF(AND(Plan!$G9<=B$4,Plan!$J9>=B$4),Plan!$B9,"") | C9: =IF(AND(Plan!$G9<=C$4,Plan!$J9>=C$4),Plan!$B9,"") | D9: =IF(AND(Plan!$G9<=D$4,Plan!$J9>=D$4),Plan!$B9,"") | E9: =IF(AND(Plan!$G9<=E$4,Plan!$J9>=E$4),Plan!$B9,"") | F9: =IF(AND(Plan!$G9<=F$4,Plan!$J9>=F$4),Plan!$B9,"") | G9: =IF(AND(Plan!$G9<=G$4,Plan!$J9>=G$4),Plan!$B9,"") | H9: =IF(AND(Plan!$G9<=H$4,Plan!$J9>=H$4),Plan!$B9,"") | I9: =IF(AND(Plan!$G9<=I$4,Plan!$J9>=I$4),Plan!$B9,"") | ... AR9: =IF(AND(Plan!$G9<=AR$4,Plan!$J9>=AR$4),Plan!$B9,"")
A10: =Plan!$B10 | B10: =IF(AND(Plan!$G10<=B$4,Plan!$J10>=B$4),Plan!$B10,"") | C10: =IF(AND(Plan!$G10<=C$4,Plan!$J10>=C$4),Plan!$B10,"") | D10: =IF(AND(Plan!$G10<=D$4,Plan!$J10>=D$4),Plan!$B10,"") | E10: =IF(AND(Plan!$G10<=E$4,Plan!$J10>=E$4),Plan!$B10,"") | F10: =IF(AND(Plan!$G10<=F$4,Plan!$J10>=F$4),Plan!$B10,"") | G10: =IF(AND(Plan!$G10<=G$4,Plan!$J10>=G$4),Plan!$B10,"") | H10: =IF(AND(Plan!$G10<=H$4,Plan!$J10>=H$4),Plan!$B10,"") | I10: =IF(AND(Plan!$G10<=I$4,Plan!$J10>=I$4),Plan!$B10,"") | ... AR10: =IF(AND(Plan!$G10<=AR$4,Plan!$J10>=AR$4),Plan!$B10,"")
A11: =Plan!$B11 | B11: =IF(AND(Plan!$G11<=B$4,Plan!$J11>=B$4),Plan!$B11,"") | C11: =IF(AND(Plan!$G11<=C$4,Plan!$J11>=C$4),Plan!$B11,"") | D11: =IF(AND(Plan!$G11<=D$4,Plan!$J11>=D$4),Plan!$B11,"") | E11: =IF(AND(Plan!$G11<=E$4,Plan!$J11>=E$4),Plan!$B11,"") | F11: =IF(AND(Plan!$G11<=F$4,Plan!$J11>=F$4),Plan!$B11,"") | G11: =IF(AND(Plan!$G11<=G$4,Plan!$J11>=G$4),Plan!$B11,"") | H11: =IF(AND(Plan!$G11<=H$4,Plan!$J11>=H$4),Plan!$B11,"") | I11: =IF(AND(Plan!$G11<=I$4,Plan!$J11>=I$4),Plan!$B11,"") | ... AR11: =IF(AND(Plan!$G11<=AR$4,Plan!$J11>=AR$4),Plan!$B11,"")
A12: =Plan!$B12 | B12: =IF(AND(Plan!$G12<=B$4,Plan!$J12>=B$4),Plan!$B12,"") | C12: =IF(AND(Plan!$G12<=C$4,Plan!$J12>=C$4),Plan!$B12,"") | D12: =IF(AND(Plan!$G12<=D$4,Plan!$J12>=D$4),Plan!$B12,"") | E12: =IF(AND(Plan!$G12<=E$4,Plan!$J12>=E$4),Plan!$B12,"") | F12: =IF(AND(Plan!$G12<=F$4,Plan!$J12>=F$4),Plan!$B12,"") | G12: =IF(AND(Plan!$G12<=G$4,Plan!$J12>=G$4),Plan!$B12,"") | H12: =IF(AND(Plan!$G12<=H$4,Plan!$J12>=H$4),Plan!$B12,"") | I12: =IF(AND(Plan!$G12<=I$4,Plan!$J12>=I$4),Plan!$B12,"") | ... AR12: =IF(AND(Plan!$G12<=AR$4,Plan!$J12>=AR$4),Plan!$B12,"")
A13: =Plan!$B13 | B13: =IF(AND(Plan!$G13<=B$4,Plan!$J13>=B$4),Plan!$B13,"") | C13: =IF(AND(Plan!$G13<=C$4,Plan!$J13>=C$4),Plan!$B13,"") | D13: =IF(AND(Plan!$G13<=D$4,Plan!$J13>=D$4),Plan!$B13,"") | E13: =IF(AND(Plan!$G13<=E$4,Plan!$J13>=E$4),Plan!$B13,"") | F13: =IF(AND(Plan!$G13<=F$4,Plan!$J13>=F$4),Plan!$B13,"") | G13: =IF(AND(Plan!$G13<=G$4,Plan!$J13>=G$4),Plan!$B13,"") | H13: =IF(AND(Plan!$G13<=H$4,Plan!$J13>=H$4),Plan!$B13,"") | I13: =IF(AND(Plan!$G13<=I$4,Plan!$J13>=I$4),Plan!$B13,"") | ... AR13: =IF(AND(Plan!$G13<=AR$4,Plan!$J13>=AR$4),Plan!$B13,"")
A14: =Plan!$B14 | B14: =IF(AND(Plan!$G14<=B$4,Plan!$J14>=B$4),Plan!$B14,"") | C14: =IF(AND(Plan!$G14<=C$4,Plan!$J14>=C$4),Plan!$B14,"") | D14: =IF(AND(Plan!$G14<=D$4,Plan!$J14>=D$4),Plan!$B14,"") | E14: =IF(AND(Plan!$G14<=E$4,Plan!$J14>=E$4),Plan!$B14,"") | F14: =IF(AND(Plan!$G14<=F$4,Plan!$J14>=F$4),Plan!$B14,"") | G14: =IF(AND(Plan!$G14<=G$4,Plan!$J14>=G$4),Plan!$B14,"") | H14: =IF(AND(Plan!$G14<=H$4,Plan!$J14>=H$4),Plan!$B14,"") | I14: =IF(AND(Plan!$G14<=I$4,Plan!$J14>=I$4),Plan!$B14,"") | ... AR14: =IF(AND(Plan!$G14<=AR$4,Plan!$J14>=AR$4),Plan!$B14,"")
A15: =Plan!$B15 | B15: =IF(AND(Plan!$G15<=B$4,Plan!$J15>=B$4),Plan!$B15,"") | C15: =IF(AND(Plan!$G15<=C$4,Plan!$J15>=C$4),Plan!$B15,"") | D15: =IF(AND(Plan!$G15<=D$4,Plan!$J15>=D$4),Plan!$B15,"") | E15: =IF(AND(Plan!$G15<=E$4,Plan!$J15>=E$4),Plan!$B15,"") | F15: =IF(AND(Plan!$G15<=F$4,Plan!$J15>=F$4),Plan!$B15,"") | G15: =IF(AND(Plan!$G15<=G$4,Plan!$J15>=G$4),Plan!$B15,"") | H15: =IF(AND(Plan!$G15<=H$4,Plan!$J15>=H$4),Plan!$B15,"") | I15: =IF(AND(Plan!$G15<=I$4,Plan!$J15>=I$4),Plan!$B15,"") | ... AR15: =IF(AND(Plan!$G15<=AR$4,Plan!$J15>=AR$4),Plan!$B15,"")
A16: =Plan!$B16 | B16: =IF(AND(Plan!$G16<=B$4,Plan!$J16>=B$4),Plan!$B16,"") | C16: =IF(AND(Plan!$G16<=C$4,Plan!$J16>=C$4),Plan!$B16,"") | D16: =IF(AND(Plan!$G16<=D$4,Plan!$J16>=D$4),Plan!$B16,"") | E16: =IF(AND(Plan!$G16<=E$4,Plan!$J16>=E$4),Plan!$B16,"") | F16: =IF(AND(Plan!$G16<=F$4,Plan!$J16>=F$4),Plan!$B16,"") | G16: =IF(AND(Plan!$G16<=G$4,Plan!$J16>=G$4),Plan!$B16,"") | H16: =IF(AND(Plan!$G16<=H$4,Plan!$J16>=H$4),Plan!$B16,"") | I16: =IF(AND(Plan!$G16<=I$4,Plan!$J16>=I$4),Plan!$B16,"") | ... AR16: =IF(AND(Plan!$G16<=AR$4,Plan!$J16>=AR$4),Plan!$B16,"")
... A18: =Plan!$B18 | B18: =IF(AND(Plan!$G18<=B$4,Plan!$J18>=B$4),Plan!$B18,"") | C18: =IF(AND(Plan!$G18<=C$4,Plan!$J18>=C$4),Plan!$B18,"") | D18: =IF(AND(Plan!$G18<=D$4,Plan!$J18>=D$4),Plan!$B18,"") | E18: =IF(AND(Plan!$G18<=E$4,Plan!$J18>=E$4),Plan!$B18,"") | F18: =IF(AND(Plan!$G18<=F$4,Plan!$J18>=F$4),Plan!$B18,"") | G18: =IF(AND(Plan!$G18<=G$4,Plan!$J18>=G$4),Plan!$B18,"") | H18: =IF(AND(Plan!$G18<=H$4,Plan!$J18>=H$4),Plan!$B18,"") | I18: =IF(AND(Plan!$G18<=I$4,Plan!$J18>=I$4),Plan!$B18,"") | ... AR18: =IF(AND(Plan!$G18<=AR$4,Plan!$J18>=AR$4),Plan!$B18,"")
A19: Sites live | B19: =SUMPRODUCT((Plan!$G$5:$G$18<=B$4)*(Plan!$J$5:$J$18>=B$4)) | C19: =SUMPRODUCT((Plan!$G$5:$G$18<=C$4)*(Plan!$J$5:$J$18>=C$4)) | D19: =SUMPRODUCT((Plan!$G$5:$G$18<=D$4)*(Plan!$J$5:$J$18>=D$4)) | E19: =SUMPRODUCT((Plan!$G$5:$G$18<=E$4)*(Plan!$J$5:$J$18>=E$4)) | F19: =SUMPRODUCT((Plan!$G$5:$G$18<=F$4)*(Plan!$J$5:$J$18>=F$4)) | G19: =SUMPRODUCT((Plan!$G$5:$G$18<=G$4)*(Plan!$J$5:$J$18>=G$4)) | H19: =SUMPRODUCT((Plan!$G$5:$G$18<=H$4)*(Plan!$J$5:$J$18>=H$4)) | I19: =SUMPRODUCT((Plan!$G$5:$G$18<=I$4)*(Plan!$J$5:$J$18>=I$4)) | ... AR19: =SUMPRODUCT((Plan!$G$5:$G$18<=AR$4)*(Plan!$J$5:$J$18>=AR$4))
A21: Team 1 | B21: =SUMPRODUCT((Plan!$F$5:$F$18=1)*(Plan!$G$5:$G$18<=B$4)*(Plan!$J$5:$J$18>=B$4)) | C21: =SUMPRODUCT((Plan!$F$5:$F$18=1)*(Plan!$G$5:$G$18<=C$4)*(Plan!$J$5:$J$18>=C$4)) | D21: =SUMPRODUCT((Plan!$F$5:$F$18=1)*(Plan!$G$5:$G$18<=D$4)*(Plan!$J$5:$J$18>=D$4)) | E21: =SUMPRODUCT((Plan!$F$5:$F$18=1)*(Plan!$G$5:$G$18<=E$4)*(Plan!$J$5:$J$18>=E$4)) | F21: =SUMPRODUCT((Plan!$F$5:$F$18=1)*(Plan!$G$5:$G$18<=F$4)*(Plan!$J$5:$J$18>=F$4)) | G21: =SUMPRODUCT((Plan!$F$5:$F$18=1)*(Plan!$G$5:$G$18<=G$4)*(Plan!$J$5:$J$18>=G$4)) | H21: =SUMPRODUCT((Plan!$F$5:$F$18=1)*(Plan!$G$5:$G$18<=H$4)*(Plan!$J$5:$J$18>=H$4)) | I21: =SUMPRODUCT((Plan!$F$5:$F$18=1)*(Plan!$G$5:$G$18<=I$4)*(Plan!$J$5:$J$18>=I$4)) | ... AR21: =SUMPRODUCT((Plan!$F$5:$F$18=1)*(Plan!$G$5:$G$18<=AR$4)*(Plan!$J$5:$J$18>=AR$4))
A22: Team 2 | B22: =SUMPRODUCT((Plan!$F$5:$F$18=2)*(Plan!$G$5:$G$18<=B$4)*(Plan!$J$5:$J$18>=B$4)) | C22: =SUMPRODUCT((Plan!$F$5:$F$18=2)*(Plan!$G$5:$G$18<=C$4)*(Plan!$J$5:$J$18>=C$4)) | D22: =SUMPRODUCT((Plan!$F$5:$F$18=2)*(Plan!$G$5:$G$18<=D$4)*(Plan!$J$5:$J$18>=D$4)) | E22: =SUMPRODUCT((Plan!$F$5:$F$18=2)*(Plan!$G$5:$G$18<=E$4)*(Plan!$J$5:$J$18>=E$4)) | F22: =SUMPRODUCT((Plan!$F$5:$F$18=2)*(Plan!$G$5:$G$18<=F$4)*(Plan!$J$5:$J$18>=F$4)) | G22: =SUMPRODUCT((Plan!$F$5:$F$18=2)*(Plan!$G$5:$G$18<=G$4)*(Plan!$J$5:$J$18>=G$4)) | H22: =SUMPRODUCT((Plan!$F$5:$F$18=2)*(Plan!$G$5:$G$18<=H$4)*(Plan!$J$5:$J$18>=H$4)) | I22: =SUMPRODUCT((Plan!$F$5:$F$18=2)*(Plan!$G$5:$G$18<=I$4)*(Plan!$J$5:$J$18>=I$4)) | ... AR22: =SUMPRODUCT((Plan!$F$5:$F$18=2)*(Plan!$G$5:$G$18<=AR$4)*(Plan!$J$5:$J$18>=AR$4))
A23: Team 3 | B23: =SUMPRODUCT((Plan!$F$5:$F$18=3)*(Plan!$G$5:$G$18<=B$4)*(Plan!$J$5:$J$18>=B$4)) | C23: =SUMPRODUCT((Plan!$F$5:$F$18=3)*(Plan!$G$5:$G$18<=C$4)*(Plan!$J$5:$J$18>=C$4)) | D23: =SUMPRODUCT((Plan!$F$5:$F$18=3)*(Plan!$G$5:$G$18<=D$4)*(Plan!$J$5:$J$18>=D$4)) | E23: =SUMPRODUCT((Plan!$F$5:$F$18=3)*(Plan!$G$5:$G$18<=E$4)*(Plan!$J$5:$J$18>=E$4)) | F23: =SUMPRODUCT((Plan!$F$5:$F$18=3)*(Plan!$G$5:$G$18<=F$4)*(Plan!$J$5:$J$18>=F$4)) | G23: =SUMPRODUCT((Plan!$F$5:$F$18=3)*(Plan!$G$5:$G$18<=G$4)*(Plan!$J$5:$J$18>=G$4)) | H23: =SUMPRODUCT((Plan!$F$5:$F$18=3)*(Plan!$G$5:$G$18<=H$4)*(Plan!$J$5:$J$18>=H$4)) | I23: =SUMPRODUCT((Plan!$F$5:$F$18=3)*(Plan!$G$5:$G$18<=I$4)*(Plan!$J$5:$J$18>=I$4)) | ... AR23: =SUMPRODUCT((Plan!$F$5:$F$18=3)*(Plan!$G$5:$G$18<=AR$4)*(Plan!$J$5:$J$18>=AR$4))
A25: Peak concurrent | B25: =MAX($B$19:$AR$19) | C25: Teams available | D25: =Reference!$B$5
A26: Cutovers in a blackout week | B26: =SUMPRODUCT($B$3:$AR$3,$B$19:$AR$19) | C26: Must be zero

Sheet Checks
A1: Constraint verification
A2: Every result computes from the Plan and Timeline sheets.
A4: Constraint | B4: Test | C4: Result | D4: Detail
A5: Master data, CHA | B5: CHA starts after BRD completes | C5: =IF(Plan!G8>Plan!J5,"Pass","FAIL") | D5: CHA consumes material master owned by BRD
A6: Master data, CHA | B6: CHA starts after HAL completes | C6: =IF(Plan!G8>Plan!J6,"Pass","FAIL") | D6: CHA consumes customer master owned by HAL
A7: Master data, COR | B7: COR starts after BRD completes | C7: =IF(Plan!G9>Plan!J5,"Pass","FAIL") | D7: COR consumes material master owned by BRD
A8: Master data, COR | B8: COR starts after KIN completes | C8: =IF(Plan!G9>Plan!J7,"Pass","FAIL") | D8: COR consumes vendor master owned by KIN
A9: Master data, ANT | B9: ANT starts after BRD completes | C9: =IF(Plan!G10>Plan!J5,"Pass","FAIL") | D9: ANT consumes material master owned by BRD
A10: Master data, ANT | B10: ANT starts after KIN completes | C10: =IF(Plan!G10>Plan!J7,"Pass","FAIL") | D10: ANT consumes vendor master owned by KIN
A11: Master data, ROT | B11: ROT starts after BRD completes | C11: =IF(Plan!G11>Plan!J5,"Pass","FAIL") | D11: ROT consumes material master owned by BRD
A12: Master data, ROT | B12: ROT starts after KIN completes | C12: =IF(Plan!G11>Plan!J7,"Pass","FAIL") | D12: ROT consumes vendor master owned by KIN
A13: Master data, SAR | B13: SAR starts after BRD completes | C13: =IF(Plan!G12>Plan!J5,"Pass","FAIL") | D13: SAR consumes material master owned by BRD
A14: Master data, SAR | B14: SAR starts after HAL completes | C14: =IF(Plan!G12>Plan!J6,"Pass","FAIL") | D14: SAR consumes customer master owned by HAL
A15: Master data, GDA | B15: GDA starts after BRD completes | C15: =IF(Plan!G13>Plan!J5,"Pass","FAIL") | D15: GDA consumes material master owned by BRD
A16: Master data, GDA | B16: GDA starts after HAL completes | C16: =IF(Plan!G13>Plan!J6,"Pass","FAIL") | D16: GDA consumes customer master owned by HAL
A17: Master data, LYO | B17: LYO starts after BRD completes | C17: =IF(Plan!G14>Plan!J5,"Pass","FAIL") | D17: LYO consumes material master owned by BRD
A18: Master data, TUR | B18: TUR starts after BRD completes | C18: =IF(Plan!G15>Plan!J5,"Pass","FAIL") | D18: TUR consumes material master owned by BRD
A19: Master data, MOB | B19: MOB starts after BRD completes | C19: =IF(Plan!G16>Plan!J5,"Pass","FAIL") | D19: MOB consumes material master owned by BRD
A20: Master data, MOB | B20: MOB starts after HAL completes | C20: =IF(Plan!G16>Plan!J6,"Pass","FAIL") | D20: MOB consumes customer master owned by HAL
A21: Master data, PEN | B21: PEN starts after BRD completes | C21: =IF(Plan!G17>Plan!J5,"Pass","FAIL") | D21: PEN consumes material master owned by BRD
A22: Master data, VAL | B22: VAL starts after BRD completes | C22: =IF(Plan!G18>Plan!J5,"Pass","FAIL") | D22: VAL consumes material master owned by BRD
A23: Validation, COR | B23: Live week is the week after cutover plus the validation period | C23: =IF(Plan!K9=Plan!J9+1+Reference!$B$6,"Pass","FAIL") | D23: The site is not live until validation completes
A24: Shutdown window, SAR | B24: SAR starts in its stated shutdown week | C24: =IF(Plan!G12=INDEX(Reference!$H$11:$H$24,MATCH(Plan!$B12,Reference!$A$11:$A$24,0)),"Pass","FAIL") | D24: Continuous process plant; the turnaround date is fixed a year ahead
A25: Shutdown window, MOB | B25: MOB starts in its stated shutdown week | C25: =IF(Plan!G16=INDEX(Reference!$H$11:$H$24,MATCH(Plan!$B16,Reference!$A$11:$A$24,0)),"Pass","FAIL") | D25: Continuous process plant; the turnaround date is fixed a year ahead
A26: Blackouts, BRD | B26: No blackout week falls inside the cutover | C26: =IF(SUMPRODUCT((Reference!$B$26:$L$26>=Plan!$G5)*(Reference!$B$26:$L$26<=Plan!$J5))=0,"Pass","FAIL")
A27: Blackouts, HAL | B27: No blackout week falls inside the cutover | C27: =IF(SUMPRODUCT((Reference!$B$26:$L$26>=Plan!$G6)*(Reference!$B$26:$L$26<=Plan!$J6))=0,"Pass","FAIL")
A28: Blackouts, KIN | B28: No blackout week falls inside the cutover | C28: =IF(SUMPRODUCT((Reference!$B$26:$L$26>=Plan!$G7)*(Reference!$B$26:$L$26<=Plan!$J7))=0,"Pass","FAIL")
A29: Blackouts, CHA | B29: No blackout week falls inside the cutover | C29: =IF(SUMPRODUCT((Reference!$B$26:$L$26>=Plan!$G8)*(Reference!$B$26:$L$26<=Plan!$J8))=0,"Pass","FAIL")
A30: Blackouts, COR | B30: No blackout week falls inside the cutover | C30: =IF(SUMPRODUCT((Reference!$B$26:$L$26>=Plan!$G9)*(Reference!$B$26:$L$26<=Plan!$J9))=0,"Pass","FAIL")
A31: Blackouts, ANT | B31: No blackout week falls inside the cutover | C31: =IF(SUMPRODUCT((Reference!$B$26:$L$26>=Plan!$G10)*(Reference!$B$26:$L$26<=Plan!$J10))=0,"Pass","FAIL")
A32: Blackouts, ROT | B32: No blackout week falls inside the cutover | C32: =IF(SUMPRODUCT((Reference!$B$26:$L$26>=Plan!$G11)*(Reference!$B$26:$L$26<=Plan!$J11))=0,"Pass","FAIL")
A33: Blackouts, SAR | B33: No blackout week falls inside the cutover | C33: =IF(SUMPRODUCT((Reference!$B$26:$L$26>=Plan!$G12)*(Reference!$B$26:$L$26<=Plan!$J12))=0,"Pass","FAIL")
A34: Blackouts, GDA | B34: No blackout week falls inside the cutover | C34: =IF(SUMPRODUCT((Reference!$B$26:$L$26>=Plan!$G13)*(Reference!$B$26:$L$26<=Plan!$J13))=0,"Pass","FAIL")
A35: Blackouts, LYO | B35: No blackout week falls inside the cutover | C35: =IF(SUMPRODUCT((Reference!$B$26:$L$26>=Plan!$G14)*(Reference!$B$26:$L$26<=Plan!$J14))=0,"Pass","FAIL")
A36: Blackouts, TUR | B36: No blackout week falls inside the cutover | C36: =IF(SUMPRODUCT((Reference!$B$26:$L$26>=Plan!$G15)*(Reference!$B$26:$L$26<=Plan!$J15))=0,"Pass","FAIL")
A37: Blackouts, MOB | B37: No blackout week falls inside the cutover | C37: =IF(SUMPRODUCT((Reference!$B$26:$L$26>=Plan!$G16)*(Reference!$B$26:$L$26<=Plan!$J16))=0,"Pass","FAIL")
... A39: Blackouts, VAL | B39: No blackout week falls inside the cutover | C39: =IF(SUMPRODUCT((Reference!$B$26:$L$26>=Plan!$G18)*(Reference!$B$26:$L$26<=Plan!$J18))=0,"Pass","FAIL")
A40: Team capacity | B40: No week requires more teams than are available | C40: =IF(MAX(Timeline!$B$19:$AR$19)<=Reference!$B$5,"Pass","FAIL") | D40: Peak concurrency against the deployment teams available
A41: Deadline | B41: Every site live on or before the support deadline | C41: =IF(MAX(Plan!K5:K18)<=Reference!$B$8,"Pass","FAIL") | D41: Cork's live date is the end of validation, not the end of cutover
A42: Durations | B42: Team weeks consumed match the site profile | C42: =IF(SUM(Plan!I5:I18)=SUM(Reference!$G$11:$G$24),"Pass","FAIL") | D42: No duration has been shortened to make the plan fit
...

Sheet Sequencing
A1: Why the sequence is what it is
A4: The order is set by freedom of movement, not by size
A5: 11 of the fourteen sites cannot start until Bridgnorth completes, because Bridgnorth owns material master. Bridgnorth therefore leads regardless of anything else. Halesworth and Kinloss own the other two master domains and run alongside it, so all three teams are committed in wave one and the dependency chain is released in five weeks.
A7: Charleston is the largest site and does not go first
A8: Charleston has 580 users and is the obvious wave one candidate on any size-ordered plan. It depends on both Bridgnorth and Halesworth and cannot start until week 10. Sequencing by size is the error that sank the first internal attempt.
A10: Cork is the smallest site and goes second
A11: Cork has 150 users and would be last on any plan ordered by size or by revenue. It is GMP regulated and needs 12 weeks of computer system validation after the technical cutover before it can transact. Its cutover takes 3 weeks, so it must begin no later than programme week 28 to be live before support ends. Placing it early removes the exposure entirely and costs nothing, because it is small enough to run beside a larger site.
A13: Sarnia and Mobile are fixed points, not choices
A14: Both run continuous plant and can only begin in their annual maintenance shutdown. Sarnia's window is programme week 24 and Mobile's is week 33. The rest of the plan is built around them rather than the reverse, because those dates are set by turnaround contractors and will not move.
A16: The blackouts remove a quarter of the calendar
A17: Eleven of the 43 programme weeks are unavailable: the week containing each quarter end and the week before it, and the first three weeks of January. They fall in clusters, so the usable calendar is four blocks rather than a continuous run. An evenly spread plan lands in them, which is what happened to the second internal attempt.
A19: Where the float is, and what it does not protect
... A23: A slip on Bridgnorth moves 11 sites. A slip that causes Sarnia or Mobile to miss its shutdown window moves that site by a full year, which is past the deadline and past the point at which the vendor will answer a support call. Those three sites carry the programme; the rest have room.
